<?xml version="1.0" encoding="utf-8"?>
<!-- =================================================================================== -->
<!-- |    This document was autogenerated by xacro from ballbot_plus_pybullet_wBarrettHands.urdf.xacro | -->
<!-- |    EDITING THIS FILE BY HAND IS NOT RECOMMENDED                                 | -->
<!-- =================================================================================== -->
<robot name="ballbot">
  <!-- CAD -->
  <material name="black">
    <color rgba="0.0 0.0 0.0 1.0"/>
  </material>
  <material name="blue">
    <color rgba="0.0 0.0 0.8 1.0"/>
  </material>
  <material name="green">
    <color rgba="0.0 0.8 0.0 1.0"/>
  </material>
  <material name="dark_grey">
    <color rgba="0.2 0.2 0.2 1.0"/>
  </material>
  <material name="grey">
    <color rgba="0.5 0.5 0.5 1.0"/>
  </material>
  <material name="light_grey">
    <color rgba="0.8 0.8 0.8 1.0"/>
  </material>
  <material name="orange">
    <color rgba="1.0 0.423529411765 0.0392156862745 1.0"/>
  </material>
  <material name="brown">
    <color rgba="0.870588235294 0.811764705882 0.764705882353 1.0"/>
  </material>
  <material name="white">
    <color rgba="1.0 1.0 1.0 1.0"/>
  </material>
  <material name="yellow">
    <color rgba="0.8 0.68 0 1"/>
  </material>
  <material name="red">
    <color rgba="1.0 0.0 0.0 1"/>
  </material>
  <material name="aluminum">
    <color rgba="0.5 0.5 0.5 1"/>
  </material>
  <!-- Includes -->
  <!-- xacro:include filename="$(find ballbot_arm_description)/xacro/materials.xacro" /-->
  <!-- Use of macros to assemble the robot -->
  <link name="Link_Body">
    <inertial>
      <origin xyz="0.0 0.0 0.7025"/>
      <mass value="64.86"/>
      <inertia ixx="10.61648" ixy="0.00000" ixz="0.00000" iyy="10.61648" iyz="0.00000" izz="0.66440"/>
    </inertial>
    <visual>
      <origin rpy="0 0 1.57079632679" xyz="0 0 0"/>
      <geometry>
        <mesh filename="./ballbot_arm/meshes/v2020/ballbot_body_v2021.stl"/>
      </geometry>
      <material name="yellow"/>
    </visual>
    <collision>
      <origin rpy="0 0 1.57079632679" xyz="0 0 0.7025"/>
      <geometry>
        <cylinder length="1.405" radius="0.184"/>
      </geometry>
    </collision>
  </link>
  <joint name="JBodytoBall" type="revolute">
    <origin rpy="0.0 0.0 0.0" xyz="0.0 0.0 0.0"/>
    <parent link="Link_Body"/>
    <child link="Link_Ball"/>
    <!-- <limit  velocity="1.0"/> -->
    <axis xyz="0 0 1"/>
  </joint>
  <link name="Link_Ball">
    <inertial>
      <origin xyz="0.0 0.0 0.0"/>
      <mass value="2.72"/>
      <inertia ixx="0.01220" ixy="0.00000" ixz="0.00000" iyy="0.01220" iyz="0.00000" izz="0.01220"/>
    </inertial>
    <visual>
      <origin rpy="0.0 0.0 0.0" xyz="0.0 0.0 0.0"/>
      <geometry>
        <sphere radius="0.105838"/>
      </geometry>
      <material name="orange"/>
    </visual>
    <collision>
      <origin rpy="0 0 0" xyz="0 0 0"/>
      <geometry>
        <sphere radius="0.105838"/>
      </geometry>
    </collision>
  </link>
  <link name="laser">
    <visual>
      <!-- barrel -->
      <origin rpy="0 0 0" xyz="0 0 0"/>
      <geometry>
        <cylinder length=".03" radius="0.02"/>
      </geometry>
      <material name="black"/>
    </visual>
    <inertial>
      <mass value="0.010"/>
      <origin xyz="0 0 0"/>
      <inertia ixx="0.0001" ixy="0.0" ixz="0.0" iyy="0.0001" iyz="0.0" izz="0.0001"/>
    </inertial>
  </link>
  <joint name="real_laser_joint" type="fixed">
    <origin rpy="0 0 0" xyz="0 0.165 0.67"/>
    <parent link="Link_Body"/>
    <child link="laser"/>
  </joint>
  <link name="laser_box">
    <visual>
      <!-- case -->
      <origin rpy="0 0 0" xyz="0 0 -.035"/>
      <geometry>
        <box size=".05 .05 .04"/>
      </geometry>
      <material name="dark_grey"/>
    </visual>
    <inertial>
      <mass value="0.120"/>
      <origin xyz="0 0 0"/>
      <inertia ixx="0.0001" ixy="0.0" ixz="0.0" iyy="0.0001" iyz="0.0" izz="0.0001"/>
    </inertial>
  </link>
  <joint name="laser_bottom" type="fixed">
    <origin rpy="0 0 0" xyz="0 0 0"/>
    <parent link="laser"/>
    <child link="laser_box"/>
  </joint>
  <joint name="turret_pan" type="revolute">
    <origin rpy="0 0 1.57079632679" xyz="0 0 1.405"/>
    <parent link="Link_Body"/>
    <child link="turret_plate_link"/>
    <limit effort="1000." lower="-6.1" upper="6.1" velocity="1.0"/>
    <axis xyz="0 0 1"/>
    <dynamics damping="1.0" friction="1.0"/>
  </joint>
  <link name="turret_plate_link">
    <visual>
      <origin rpy="0 0 0" xyz="0.0 0.0 0.0"/>
      <geometry>
        <mesh filename="./ballbot_arm/meshes/v2020/turret_pan.stl"/>
      </geometry>
      <material name="grey"/>
    </visual>
    <inertial>
      <origin xyz="0.0 0.0 0.0"/>
      <mass value="0.0"/>
      <inertia ixx="0.0" ixy="0.00000" ixz="0.00000" iyy="0.0" iyz="0.00000" izz="0.0"/>
    </inertial>
  </link>
  <joint name="turret_tilt" type="revolute">
    <origin rpy="1.57079632679 0 3.14159265359" xyz="0.15557 -0.0347980 0.0541020"/>
    <parent link="turret_plate_link"/>
    <child link="turret_tilt_link"/>
    <limit effort="1000.0" lower="-0.05" upper="1.57079632679" velocity="1.0"/>
    <axis xyz="0 0 1"/>
    <dynamics damping="1.0" friction="1.0"/>
  </joint>
  <link name="turret_tilt_link">
    <visual>
      <origin rpy="0 0 0" xyz="0.0 0.0 0.0"/>
      <geometry>
        <mesh filename="./ballbot_arm/meshes/v2020/turret_tilt.stl"/>
      </geometry>
      <material name="brown"/>
    </visual>
    <inertial>
      <origin xyz="0.0 0.0 0.0"/>
      <mass value="0.0"/>
      <inertia ixx="0.0" ixy="0.00000" ixz="0.00000" iyy="0.0" iyz="0.00000" izz="0.0"/>
    </inertial>
  </link>
  <joint name="camera_rgb_joint" type="fixed">
    <origin rpy="-1.57079632679 3.14159265359 0" xyz="0.01905 0.132906 0.053721"/>
    <parent link="turret_tilt_link"/>
    <child link="camera_rgb_frame"/>
  </joint>
  <link name="camera_rgb_frame"/>
  <joint name="camera_rgb_optical_joint" type="fixed">
    <origin rpy="-1.57079632679 0 -1.57079632679" xyz="0 0 0"/>
    <parent link="camera_rgb_frame"/>
    <child link="camera_rgb_optical_frame"/>
  </joint>
  <link name="camera_rgb_optical_frame"/>
  <joint name="camera_joint" type="fixed">
    <origin rpy="0 0 0" xyz="0 -0.022 0"/>
    <parent link="camera_rgb_frame"/>
    <child link="camera_link"/>
  </joint>
  <link name="camera_link">
    <visual>
      <origin rpy="0 0 0" xyz="-0.015 0.0035 0.004"/>
      <geometry>
        <mesh filename="./ballbot_arm/meshes/sensors/xtion_pro_camera.dae"/>
      </geometry>
    </visual>
    <collision>
      <origin rpy="0 0 0" xyz="0.0 0.0 0.0"/>
      <geometry>
        <box size="0.0730 0.2760 0.0720"/>
      </geometry>
    </collision>
    <inertial>
      <mass value="0.170"/>
      <origin xyz="0 0 0"/>
      <inertia ixx="0.001152600" ixy="0.0" ixz="0.0" iyy="0.000148934" iyz="0.0" izz="0.001154654"/>
    </inertial>
  </link>
  <joint name="camera_depth_joint" type="fixed">
    <origin rpy="0 0 0" xyz="0 0.027 0"/>
    <parent link="camera_rgb_frame"/>
    <child link="camera_depth_frame"/>
  </joint>
  <link name="camera_depth_frame"/>
  <joint name="camera_depth_optical_joint" type="fixed">
    <origin rpy="-1.57079632679 0 -1.57079632679" xyz="0 0 0"/>
    <parent link="camera_depth_frame"/>
    <child link="camera_depth_optical_frame"/>
  </joint>
  <link name="camera_depth_optical_frame"/>
  <gazebo reference="camera_link">
    <sensor name="camera" type="depth">
      <always_on>true</always_on>
      <update_rate>20.0</update_rate>
      <camera>
        <horizontal_fov>1.0471975512</horizontal_fov>
        <image>
          <format>B8G8R8</format>
          <width>640</width>
          <height>480</height>
        </image>
        <clip>
          <near>0.05</near>
          <far>8.0</far>
        </clip>
      </camera>
      <plugin filename="libgazebo_ros_openni_kinect.so" name="kinect_camera_controller">
        <cameraName>camera</cameraName>
        <alwaysOn>true</alwaysOn>
        <updateRate>10</updateRate>
        <imageTopicName>rgb/image_raw</imageTopicName>
        <depthImageTopicName>depth/image_raw</depthImageTopicName>
        <pointCloudTopicName>depth/points</pointCloudTopicName>
        <cameraInfoTopicName>rgb/camera_info</cameraInfoTopicName>
        <depthImageCameraInfoTopicName>depth/camera_info</depthImageCameraInfoTopicName>
        <frameName>camera_depth_optical_frame</frameName>
        <baseline>0.1</baseline>
        <distortion_k1>0.0</distortion_k1>
        <distortion_k2>0.0</distortion_k2>
        <distortion_k3>0.0</distortion_k3>
        <distortion_t1>0.0</distortion_t1>
        <distortion_t2>0.0</distortion_t2>
        <pointCloudCutoff>0.4</pointCloudCutoff>
      </plugin>
    </sensor>
  </gazebo>
  <!-- ====================================== -->
  <!-- Right Arm -->
  <joint name="JRA0" type="fixed">
    <!--origin xyz="-0.00635 -0.12314 1.32915" rpy="${-PI/2} ${-PI/2} ${PI}"/-->
    <origin rpy="-1.57079632679 -1.57079632679 -1.57079632679" xyz="0.12314 -0.00635 1.32915"/>
    <parent link="Link_Body"/>
    <child link="RArm0"/>
    <axis xyz="0 0 1"/>
    <dynamics damping="1.0" friction="1.0"/>
  </joint>
  <link name="RArm0">
    <inertial>
      <origin rpy="0 0 0" xyz="-0.00832 0.0 -0.0418"/>
      <mass value="2.367"/>
      <inertia ixx="0.00366" ixy="0.0" ixz="-0.0000208" iyy="0.00398" iyz="0.0" izz="0.00461"/>
    </inertial>
    <visual>
      <origin rpy="0 0 0" xyz="0 0 0"/>
      <geometry>
        <mesh filename="./ballbot_arm/meshes/v2020/link_base.stl"/>
      </geometry>
      <material name="grey"/>
    </visual>
    <collision>
      <origin rpy="0 0 0" xyz="0 0 0"/>
      <geometry>
        <mesh filename="./ballbot_arm/meshes/v2020/link_base.stl"/>
      </geometry>
    </collision>
  </link>
  <link name="RArm1">
    <inertial>
      <origin xyz="0.0 0.00329 0.0865"/>
      <mass value="4.181"/>
      <inertia ixx="0.0172" ixy="0.0000173" ixz="0.0" iyy="0.0170" iyz="-0.000935" izz="0.00602"/>
    </inertial>
    <visual>
      <origin rpy="0 0 3.14159265359" xyz="0.0 0.0 0.0"/>
      <geometry>
        <mesh filename="./ballbot_arm/meshes/v2020/link_shoulder_2_base.stl"/>
      </geometry>
      <material name="brown"/>
    </visual>
    <collision>
      <origin rpy="0 0 0" xyz="0.0 0.0 -0.05525"/>
      <geometry>
        <cylinder length="0.1105" radius="0.05"/>
      </geometry>
    </collision>
  </link>
  <link name="RArm2">
    <inertial>
      <origin xyz="-0.123 0.000 -0.0507"/>
      <mass value="1.832"/>
      <inertia ixx="0.00241" ixy="0.0" ixz="-0.000742" iyy="0.00559" iyz="0.0" izz="0.00563"/>
    </inertial>
    <visual>
      <origin rpy="0 0 0" xyz="0.0 0.0 0.0"/>
      <geometry>
        <mesh filename="./ballbot_arm/meshes/v2020/link_shoulder_2_uparm.stl"/>
      </geometry>
      <material name="grey"/>
    </visual>
    <collision>
      <origin rpy="0 0 0" xyz="0.0 0.0 -0.05525"/>
      <geometry>
        <cylinder length="0.1105" radius="0.05"/>
      </geometry>
    </collision>
  </link>
  <link name="RArm3">
    <inertial>
      <origin xyz="0.0 -0.00963 0.0773"/>
      <mass value="1.821"/>
      <inertia ixx="0.00375" ixy="0.0" ixz="0.0" iyy="0.00338" iyz="0.000169" izz="0.00278"/>
    </inertial>
    <visual>
      <origin rpy="0 0 0" xyz="0.0 0.0 -0.02718"/>
      <geometry>
        <mesh filename="./ballbot_arm/meshes/v2020/link_upperarm.stl"/>
      </geometry>
      <material name="brown"/>
    </visual>
    <collision>
      <origin rpy="0 0 0" xyz="0.0 0.0 -0.05525"/>
      <geometry>
        <cylinder length="0.1105" radius="0.05"/>
      </geometry>
    </collision>
  </link>
  <link name="RArm4">
    <inertial>
      <origin xyz="-0.0758 0.0594 -0.0448"/>
      <mass value="1.105"/>
      <inertia ixx="0.00186" ixy="0.000915" ixz="-0.000456" iyy="0.00276" iyz="0.000276" izz="0.00356"/>
    </inertial>
    <visual>
      <origin rpy="0 0 0" xyz="0.0 0.0 0.0"/>
      <geometry>
        <mesh filename="./ballbot_arm/meshes/v2020/link_forearm_r.stl"/>
      </geometry>
      <material name="grey"/>
    </visual>
    <collision>
      <origin rpy="0 0 0" xyz="0.0 0.0 -0.05525"/>
      <geometry>
        <cylinder length="0.1105" radius="0.05"/>
      </geometry>
    </collision>
  </link>
  <link name="RArm5">
    <inertial>
      <origin xyz="-0.00147 0.0 -0.0537"/>
      <mass value="0.973"/>
      <inertia ixx="0.00106" ixy="0.0" ixz="-0.0000188" iyy="0.00123" iyz="0.0" izz="0.00101"/>
    </inertial>
    <visual>
      <origin rpy="0 0 0" xyz="0.0 0.0 0.0"/>
      <geometry>
        <mesh filename="./ballbot_arm/meshes/v2020/link_forearm_2_wrist.stl"/>
      </geometry>
      <material name="brown"/>
    </visual>
    <collision>
      <origin rpy="0 0 0" xyz="0.0 0.0 0.0495"/>
      <geometry>
        <cylinder length="0.099" radius="0.0375"/>
      </geometry>
    </collision>
  </link>
  <link name="RArm6">
    <inertial>
      <origin xyz="0.0947 0.00543 0.0386"/>
      <mass value="1.013"/>
      <inertia ixx="0.00106" ixy="-0.0000831" ixz="-0.000236" iyy="0.00193" iyz="-0.0000139" izz="0.00215"/>
    </inertial>
    <visual>
      <origin rpy="0 0 0" xyz="0.0 0.0 0.0"/>
      <geometry>
        <mesh filename="./ballbot_arm/meshes/v2020/link_wrist_mid.stl"/>
      </geometry>
      <material name="grey"/>
    </visual>
    <collision>
      <origin rpy="0 0 0" xyz="0.0 0.0 0.0495"/>
      <geometry>
        <cylinder length="0.099" radius="0.0375"/>
      </geometry>
    </collision>
  </link>
  <link name="RArm7">
    <inertial>
      <origin xyz="0.0235 -0.000000178 0.0295"/>
      <mass value="0.195"/>
      <inertia ixx="0.000257" ixy="0.0" ixz="-0.0000691" iyy="0.000325" iyz="0.0" izz="0.000362"/>
    </inertial>
    <visual>
      <origin rpy="0 0 0" xyz="0.0 0.0 0.0"/>
      <geometry>
        <mesh filename="./ballbot_arm/meshes/v2020/link_wrist_2_hand.stl"/>
      </geometry>
      <material name="brown"/>
    </visual>
    <collision>
      <origin rpy="0 0 0" xyz="0.0 0.0 0.0495"/>
      <geometry>
        <cylinder length="0.099" radius="0.0375"/>
      </geometry>
    </collision>
  </link>
  <joint name="JRA1" type="revolute">
    <origin rpy="0.0 0.0 0.0" xyz="0.0 0.0 0.0"/>
    <parent link="RArm0"/>
    <child link="RArm1"/>
    <limit effort="30.0" lower="-2.96705972839" upper="2.96705972839" velocity="3.0"/>
    <axis xyz="0 0 1"/>
    <dynamics damping="0.7" friction="0.5"/>
  </joint>
  <joint name="JRA2" type="revolute">
    <origin rpy="-1.5707963705062866 0.0 -0.0" xyz="0.00000 0.05436 0.14900"/>
    <parent link="RArm1"/>
    <child link="RArm2"/>
    <limit effort="30.0" lower="-0.0349065850399" upper="1.57079632679" velocity="3.0"/>
    <axis xyz="0 0 1"/>
    <dynamics damping="0.7" friction="0.5"/>
  </joint>
  <joint name="JRA3" type="revolute">
    <origin rpy="3.141592653589793 -1.570796282091413 3.141592653589793" xyz="-0.17786 0.00000 -0.05436"/>
    <parent link="RArm2"/>
    <child link="RArm3"/>
    <limit effort="30.0" lower="-1.57079632679" upper="1.57079632679" velocity="3.0"/>
    <axis xyz="0 0 1"/>
    <dynamics damping="0.7" friction="0.5"/>
  </joint>
  <joint name="JRA4" type="revolute">
    <origin rpy="-2.3561944901923457 1.5707962635746238 2.3561944901923457" xyz="0.00000 -0.05436 0.08522"/>
    <parent link="RArm3"/>
    <child link="RArm4"/>
    <limit effort="30.0" lower="-0.349065850399" upper="2.79252680319" velocity="3.0"/>
    <axis xyz="0 0 1"/>
    <dynamics damping="0.7" friction="0.5"/>
  </joint>
  <joint name="JRA5" type="revolute">
    <origin rpy="0 1.57079632679 0" xyz="-0.13200 0.07000 -0.05073"/>
    <parent link="RArm4"/>
    <child link="RArm5"/>
    <limit effort="30.0" lower="-2.82743338823" upper="2.82743338823" velocity="3.0"/>
    <axis xyz="0 0 1"/>
    <dynamics damping="0.7" friction="0.5"/>
  </joint>
  <joint name="JRA6" type="revolute">
    <origin rpy="0 1.57079632679 0" xyz="-0.04115 0.0 -0.06"/>
    <parent link="RArm5"/>
    <child link="RArm6"/>
    <limit effort="30.0" lower="-1.49599650171" upper="1.49599650171" velocity="3.0"/>
    <axis xyz="0 0 1"/>
    <dynamics damping="0.7" friction="0.5"/>
  </joint>
  <joint name="JRA7" type="revolute">
    <origin rpy="1.57079632679 0.0 0.0" xyz="0.10750 0.04650 0.041150"/>
    <parent link="RArm6"/>
    <child link="RArm7"/>
    <limit effort="30.0" lower="-1.49599650171" upper="1.49599650171" velocity="3.0"/>
    <axis xyz="0 0 1"/>
    <dynamics damping="0.7" friction="0.5"/>
  </joint>
  <link name="toolR">
    <inertial>
      <origin xyz="0.0 0.0 0.0"/>
      <mass value="1e-05"/>
      <inertia ixx="0.00001" ixy="0.0" ixz="0.0" iyy="0.00001" iyz="0.0" izz="0.00001"/>
    </inertial>
  </link>
  <joint name="RArm7-toolR" type="revolute">
    <origin rpy="0 1.57079632679 0" xyz="0.155 0 0.04065"/>
    <axis xyz="0 0 1"/>
    <parent link="RArm7"/>
    <child link="toolR"/>
  </joint>
  <!-- Knob hands -->
  <!-- <xacro:knob_hand prefix="R_" parent="toolR" material="blue">
    <origin xyz="0. 0. 0." rpy="0. 0. 0."/>
  </xacro:knob_hand> -->
  <!-- Right Intel RealSense Camera -->
  <!-- <xacro:IntelD435_mount_macro prefix="R_" parent="toolR" color="grey">
      <origin xyz="0 0 0.0" rpy="0 0 ${PI}"/>
  </xacro:IntelD435_mount_macro> -->
  <!-- <sensor_d435 parent="R_D435_Mount" name="RD435_camera">
    <origin xyz="-0.064427 0 0.016981" rpy="${DEG2RAD*0} ${-DEG2RAD*80} ${DEG2RAD*0} "/>
  </sensor_d435> -->
  <!-- Right  Barrett B4277 Mount -->
  <!-- <xacro:bhand_mount_macro prefix="R_" parent="R_D435_Mount">
      <origin xyz="0 0 0.006" rpy="0 0 0"/>
  </xacro:bhand_mount_macro> -->
  <!-- Right  Barrett Hand B282 -->
  <!-- <xacro:bhand_macro name="R_bh" parent="R_B4277_link">
    <origin xyz="0 0 0.008" rpy="0 0 0" />
  </xacro:bhand_macro> -->
  <!-- <xacro:bhand_macro name="R_bh" parent="toolR">
    <origin xyz="0 0 0.0" rpy="0 0 ${PI}" />
  </xacro:bhand_macro> -->
  <joint name="R_bh_base_joint" type="fixed">
    <origin rpy="0 1.57079632679 0" xyz="0.055 0 0.04065"/>
    <parent link="RArm7"/>
    <child link="R_bh_base_link"/>
  </joint>
  <!-- HAND BASE_LINK (RED) -->
  <link name="R_bh_base_link">
    <inertial>
      <mass value="3.0"/>
      <origin xyz="0 0 0"/>
      <inertia ixx="1.0" ixy="0.0" ixz="0.0" iyy="1.0" iyz="0.0" izz="1.0"/>
    </inertial>
    <visual>
      <origin rpy="0 0 0" xyz="0 0 0"/>
      <geometry>
        <mesh filename="./barrett_hand/meshes/palm_282.dae"/>
      </geometry>
      <material name="Grey">
        <color rgba="0.75 0.75 0.75 1.0"/>
      </material>
    </visual>
    <collision>
      <origin rpy="0 0 0 " xyz="0 0 0"/>
      <geometry>
        <mesh filename="./barrett_hand/meshes/palm_282.dae"/>
      </geometry>
      <contact_coefficients kd="1.0" kp="1000.0" mu="0"/>
    </collision>
  </link>
  <!-- finger 3 -->
  <!-- finger 31 link -->
  <link name="R_bh_finger_31_link">
    <inertial>
      <mass value="0.1"/>
      <origin rpy="0 0 0" xyz="-0.046 0 0"/>
      <inertia ixx="0.01" ixy="0" ixz="0" iyy="0.01" iyz="0" izz="0.01"/>
    </inertial>
    <visual>
      <origin rpy="0 0 0" xyz="-0.04 0 0"/>
      <geometry>
        <mesh filename="./barrett_hand/meshes/knuckle_fixed.dae"/>
      </geometry>
      <material name="Black"/>
    </visual>
    <collision>
      <origin rpy="0 0 0" xyz="-0.04 0 0"/>
      <geometry>
        <mesh filename="./barrett_hand/meshes/knuckle_fixed.dae"/>
      </geometry>
      <contact_coefficients kd="1.0" kp="1000.0" mu="0"/>
    </collision>
  </link>
  <!-- joint between BH_palm_link and BH_finger_31_link -->
  <!-- finger3 is the center finger and is fixed -->
  <joint name="R_bh_j31_joint" type="fixed">
    <parent link="R_bh_base_link"/>
    <child link="R_bh_finger_31_link"/>
    <origin rpy="0 0 -1.570796327" xyz="0 0 0.0252"/>
  </joint>
  <!-- finger 32 link -->
  <link name="R_bh_finger_32_link">
    <inertial>
      <mass value="0.1"/>
      <origin rpy="0 0 0" xyz="0 0 0"/>
      <inertia ixx="0.01" ixy="0" ixz="0" iyy="0.01" iyz="0" izz="0.01"/>
    </inertial>
    <visual>
      <origin rpy="0 0 0" xyz="0 0 0"/>
      <geometry>
        <mesh filename="./barrett_hand/meshes/finger.dae"/>
      </geometry>
      <material name="Blue"/>
    </visual>
    <collision>
      <origin rpy="0 0 0" xyz="0 0 0"/>
      <geometry>
        <mesh filename="./barrett_hand/meshes/finger.dae"/>
      </geometry>
      <contact_coefficients kd="1.0" kp="1000.0" mu="0"/>
    </collision>
  </link>
  <!-- joint between BH_finger_31_link and BH_finger_32_link -->
  <joint name="R_bh_j32_joint" type="revolute">
    <parent link="R_bh_finger_31_link"/>
    <child link="R_bh_finger_32_link"/>
    <origin rpy="1.5708 -8.8281E-17 0" xyz="-0.05 0 0.0339"/>
    <axis xyz="0 0 -1"/>
    <limit effort="30.0" lower="0.0" upper="2.44" velocity="2.0"/>
    <dynamics damping="0.7" friction="1.0"/>
  </joint>
  <transmission name="R_bh_j32_transmission">
    <type>transmission_interface/SimpleTransmission</type>
    <joint name="R_bh_j32_joint">
      <hardwareInterface>hardware_interface/PositionJointInterface</hardwareInterface>
    </joint>
    <actuator name="R_bh_j32">
      <hardwareInterface>hardware_interface/PositionJointInterface</hardwareInterface>
      <mechanicalReduction>1</mechanicalReduction>
      <motorTorqueConstant>1</motorTorqueConstant>
    </actuator>
  </transmission>
  <!-- finger 33 link -->
  <link name="R_bh_finger_33_link">
    <inertial>
      <mass value="0.1"/>
      <origin rpy="0 0 0" xyz="0 0 0"/>
      <inertia ixx="0.01" ixy="0" ixz="0" iyy="0.01" iyz="0" izz="0.01"/>
    </inertial>
    <visual>
      <origin rpy="0 0 0" xyz="0 0 0"/>
      <geometry>
        <mesh filename="./barrett_hand/meshes/finger_tip.dae"/>
      </geometry>
      <material name="Blue"/>
    </visual>
    <collision>
      <origin rpy="0 0 0" xyz="0 0 0"/>
      <geometry>
        <mesh filename="./barrett_hand/meshes/finger_tip.dae"/>
      </geometry>
      <contact_coefficients kd="1.0" kp="1000.0" mu="0"/>
    </collision>
  </link>
  <!-- joint between BH_finger_32_link and BH_finger_33_link -->
  <joint name="R_bh_j33_joint" type="revolute">
    <parent link="R_bh_finger_32_link"/>
    <child link="R_bh_finger_33_link"/>
    <origin rpy="0 0 0" xyz="-0.069936 0.003 0"/>
    <axis xyz="0 0 -1"/>
    <mimic joint="R_bh_j32_joint" multiplier="0.344262295082"/>
    <limit effort="30.0" lower="0.0" upper="0.84" velocity="2.0"/>
    <dynamics damping="0.7" friction="1.0"/>
  </joint>
  <transmission name="R_bh_j33_transmission">
    <type>transmission_interface/SimpleTransmission</type>
    <joint name="R_bh_j33_joint">
      <hardwareInterface>hardware_interface/PositionJointInterface</hardwareInterface>
    </joint>
    <actuator name="R_bh_j33">
      <hardwareInterface>hardware_interface/PositionJointInterface</hardwareInterface>
      <mechanicalReduction>1</mechanicalReduction>
      <motorTorqueConstant>1</motorTorqueConstant>
    </actuator>
  </transmission>
  <!-- finger 1 -->
  <!-- finger 11 link -->
  <link name="R_bh_finger_11_link">
    <inertial>
      <mass value="0.1"/>
      <origin rpy="0 0 0" xyz="-0.046 0 0"/>
      <inertia ixx="0.01" ixy="0" ixz="0" iyy="0.01" iyz="0" izz="0.01"/>
    </inertial>
    <visual>
      <origin rpy="0 0 0" xyz="0 0 0"/>
      <geometry>
        <mesh filename="./barrett_hand/meshes/knuckle.dae"/>
      </geometry>
      <material name="Green"/>
    </visual>
    <collision>
      <origin rpy="0 0 0" xyz="0 0 0"/>
      <geometry>
        <mesh filename="./barrett_hand/meshes/knuckle.dae"/>
      </geometry>
    </collision>
  </link>
  <!-- joint between BH_palm_link and BH_finger_11_link -->
  <joint name="R_bh_j11_joint" type="revolute">
    <parent link="R_bh_base_link"/>
    <child link="R_bh_finger_11_link"/>
    <origin rpy="0 0 1.5708" xyz="-0.025 0 0.0252"/>
    <axis xyz="0 0 -1"/>
    <limit effort="30.0" lower="0" upper="3.1416" velocity="2.0"/>
    <dynamics damping="0.7" friction="1.0"/>
  </joint>
  <transmission name="R_bh_j11_transmission">
    <type>transmission_interface/SimpleTransmission</type>
    <joint name="R_bh_j11_joint">
      <hardwareInterface>hardware_interface/PositionJointInterface</hardwareInterface>
    </joint>
    <actuator name="R_bh_j11">
      <hardwareInterface>hardware_interface/PositionJointInterface</hardwareInterface>
      <mechanicalReduction>1</mechanicalReduction>
      <motorTorqueConstant>1</motorTorqueConstant>
    </actuator>
  </transmission>
  <!-- finger 12 link -->
  <link name="R_bh_finger_12_link">
    <inertial>
      <mass value="0.1"/>
      <origin rpy="0 0 0" xyz="0 0 0"/>
      <inertia ixx="0.01" ixy="0" ixz="0" iyy="0.01" iyz="0" izz="0.01"/>
    </inertial>
    <visual>
      <origin rpy="0 0 0" xyz="0 0 0"/>
      <geometry>
        <mesh filename="./barrett_hand/meshes/finger.dae"/>
      </geometry>
      <material name="Blue"/>
    </visual>
    <collision>
      <origin rpy="0 0 0" xyz="0 0 0"/>
      <geometry>
        <mesh filename="./barrett_hand/meshes/finger.dae"/>
      </geometry>
      <contact_coefficients kd="1.0" kp="1000.0" mu="0"/>
    </collision>
  </link>
  <!-- joint between BH_finger_11_link and BH_finger_12_link -->
  <joint name="R_bh_j12_joint" type="revolute">
    <parent link="R_bh_finger_11_link"/>
    <child link="R_bh_finger_12_link"/>
    <origin rpy="1.5708 0 0" xyz="-0.05 0 0.0339"/>
    <axis xyz="0 0 -1"/>
    <limit effort="30.0" lower="0.0" upper="2.44" velocity="2.0"/>
    <dynamics damping="0.7" friction="1.0"/>
  </joint>
  <transmission name="R_bh_j12_transmission">
    <type>transmission_interface/SimpleTransmission</type>
    <joint name="R_bh_j12_joint">
      <hardwareInterface>hardware_interface/PositionJointInterface</hardwareInterface>
    </joint>
    <actuator name="R_bh_j12">
      <hardwareInterface>hardware_interface/PositionJointInterface</hardwareInterface>
      <mechanicalReduction>1</mechanicalReduction>
      <motorTorqueConstant>1</motorTorqueConstant>
    </actuator>
  </transmission>
  <!-- finger 13 link -->
  <link name="R_bh_finger_13_link">
    <inertial>
      <mass value="0.1"/>
      <origin rpy="0 0 0" xyz="0 0 0"/>
      <inertia ixx="0.01" ixy="0" ixz="0" iyy="0.01" iyz="0" izz="0.01"/>
    </inertial>
    <visual>
      <origin rpy="0 0 0" xyz="0 0 0"/>
      <geometry>
        <mesh filename="./barrett_hand/meshes/finger_tip.dae"/>
      </geometry>
      <material name="Blue"/>
    </visual>
    <collision>
      <origin rpy="0 0 0" xyz="0 0 0"/>
      <geometry>
        <mesh filename="./barrett_hand/meshes/finger_tip.dae"/>
      </geometry>
      <contact_coefficients kd="1.0" kp="1000.0" mu="0"/>
    </collision>
  </link>
  <!-- joint between BH_finger_12_link and BH_finger_13_link -->
  <joint name="R_bh_j13_joint" type="revolute">
    <parent link="R_bh_finger_12_link"/>
    <child link="R_bh_finger_13_link"/>
    <origin rpy="0 0 0" xyz="-0.069936 0.003 0"/>
    <axis xyz="0 0 -1"/>
    <mimic joint="R_bh_j12_joint" multiplier="0.344262295082"/>
    <limit effort="30.0" lower="0.0" upper="0.84" velocity="2.0"/>
    <dynamics damping="0.7" friction="1.0"/>
  </joint>
  <transmission name="R_bh_j13_transmission">
    <type>transmission_interface/SimpleTransmission</type>
    <joint name="R_bh_j13_joint">
      <hardwareInterface>hardware_interface/PositionJointInterface</hardwareInterface>
    </joint>
    <actuator name="R_bh_j13">
      <hardwareInterface>hardware_interface/PositionJointInterface</hardwareInterface>
      <mechanicalReduction>1</mechanicalReduction>
      <motorTorqueConstant>1</motorTorqueConstant>
    </actuator>
  </transmission>
  <!-- finger 2 -->
  <!-- finger 21 link -->
  <link name="R_bh_finger_21_link">
    <inertial>
      <mass value="0.1"/>
      <origin rpy="0 0 0" xyz="-0.046 0 0"/>
      <inertia ixx="0.01" ixy="0" ixz="0" iyy="0.01" iyz="0" izz="0.01"/>
    </inertial>
    <visual>
      <origin rpy="0 0 0" xyz="0 0 0"/>
      <geometry>
        <mesh filename="./barrett_hand/meshes/knuckle.dae"/>
      </geometry>
      <material name="Green"/>
    </visual>
    <collision>
      <origin rpy="0 0 0" xyz="0 0 0"/>
      <geometry>
        <mesh filename="./barrett_hand/meshes/knuckle.dae"/>
      </geometry>
    </collision>
  </link>
  <!-- joint between BH_palm_link and BH_finger_21_link -->
  <joint name="R_bh_j21_joint" type="revolute">
    <parent link="R_bh_base_link"/>
    <child link="R_bh_finger_21_link"/>
    <origin rpy="0 0 1.5708" xyz="0.025 0 0.0252"/>
    <axis xyz="0 0 1"/>
    <mimic joint="R_bh_j11_joint" multiplier="1"/>
    <limit effort="30.0" lower="0" upper="3.1416" velocity="2.0"/>
    <dynamics damping="0.7" friction="1.0"/>
  </joint>
  <transmission name="R_bh_j21_transmission">
    <type>transmission_interface/SimpleTransmission</type>
    <joint name="R_bh_j21_joint">
      <hardwareInterface>hardware_interface/PositionJointInterface</hardwareInterface>
    </joint>
    <actuator name="R_bh_j21">
      <hardwareInterface>hardware_interface/PositionJointInterface</hardwareInterface>
      <mechanicalReduction>1</mechanicalReduction>
      <motorTorqueConstant>1</motorTorqueConstant>
    </actuator>
  </transmission>
  <!-- finger 12 link -->
  <link name="R_bh_finger_22_link">
    <inertial>
      <mass value="0.1"/>
      <origin rpy="0 0 0" xyz="0 0 0"/>
      <inertia ixx="0.01" ixy="0" ixz="0" iyy="0.01" iyz="0" izz="0.01"/>
    </inertial>
    <visual>
      <origin rpy="0 0 0" xyz="0 0 0"/>
      <geometry>
        <mesh filename="./barrett_hand/meshes/finger.dae"/>
      </geometry>
      <material name="Blue"/>
    </visual>
    <collision>
      <origin rpy="0 0 0" xyz="0 0 0"/>
      <geometry>
        <mesh filename="./barrett_hand/meshes/finger.dae"/>
      </geometry>
      <contact_coefficients kd="1.0" kp="1000.0" mu="0"/>
    </collision>
  </link>
  <!-- joint between BH_finger_21_link and BH_finger_22_link -->
  <joint name="R_bh_j22_joint" type="revolute">
    <parent link="R_bh_finger_21_link"/>
    <child link="R_bh_finger_22_link"/>
    <origin rpy="1.5708 -8.8281E-17 0" xyz="-0.05 0 0.0339"/>
    <axis xyz="0 0 -1"/>
    <limit effort="30.0" lower="0.0" upper="2.44" velocity="2.0"/>
    <dynamics damping="0.7" friction="1.0"/>
  </joint>
  <transmission name="R_bh_j22_transmission">
    <type>transmission_interface/SimpleTransmission</type>
    <joint name="R_bh_j22_joint">
      <hardwareInterface>hardware_interface/PositionJointInterface</hardwareInterface>
    </joint>
    <actuator name="R_bh_j22">
      <hardwareInterface>hardware_interface/PositionJointInterface</hardwareInterface>
      <mechanicalReduction>1</mechanicalReduction>
      <motorTorqueConstant>1</motorTorqueConstant>
    </actuator>
  </transmission>
  <!-- finger 23 link -->
  <link name="R_bh_finger_23_link">
    <inertial>
      <mass value="0.1"/>
      <origin rpy="0 0 0" xyz="0 0 0"/>
      <inertia ixx="0.01" ixy="0" ixz="0" iyy="0.01" iyz="0" izz="0.01"/>
    </inertial>
    <visual>
      <origin rpy="0 0 0" xyz="0 0 0"/>
      <geometry>
        <mesh filename="./barrett_hand/meshes/finger_tip.dae"/>
      </geometry>
      <material name="Blue"/>
    </visual>
    <collision>
      <origin rpy="0 0 0" xyz="0 0 0"/>
      <geometry>
        <mesh filename="./barrett_hand/meshes/finger_tip.dae"/>
      </geometry>
      <contact_coefficients kd="1.0" kp="1000.0" mu="0"/>
    </collision>
  </link>
  <!-- joint between BH_finger_22_link and BH_finger_23_link -->
  <joint name="R_bh_j23_joint" type="revolute">
    <parent link="R_bh_finger_22_link"/>
    <child link="R_bh_finger_23_link"/>
    <origin rpy="0 0 0" xyz="-0.069936 0.003 0"/>
    <axis xyz="0 0 -1"/>
    <mimic joint="R_bh_j22_joint" multiplier="0.344262295082"/>
    <limit effort="30.0" lower="0.0" upper="0.84" velocity="2.0"/>
    <dynamics damping="0.7" friction="1.0"/>
  </joint>
  <transmission name="R_bh_j23_transmission">
    <type>transmission_interface/SimpleTransmission</type>
    <joint name="R_bh_j23_joint">
      <hardwareInterface>hardware_interface/PositionJointInterface</hardwareInterface>
    </joint>
    <actuator name="R_bh_j23">
      <hardwareInterface>hardware_interface/PositionJointInterface</hardwareInterface>
      <mechanicalReduction>1</mechanicalReduction>
      <motorTorqueConstant>1</motorTorqueConstant>
    </actuator>
  </transmission>
  <gazebo>
    <plugin filename="libgazebo_mimic_plugin.so" name="mimic_plugin">
      <joint>R_bh_j11_joint</joint>
      <mimicJoint>R_bh_j21_joint</mimicJoint>
      <multiplier>1</multiplier>
    </plugin>
  </gazebo>
  <gazebo>
    <plugin filename="libgazebo_mimic_plugin.so" name="mimic_plugin">
      <joint>R_bh_j12_joint</joint>
      <mimicJoint>R_bh_j13_joint</mimicJoint>
      <multiplier>0.344</multiplier>
    </plugin>
  </gazebo>
  <gazebo>
    <plugin filename="libgazebo_mimic_plugin.so" name="mimic_plugin">
      <joint>R_bh_j22_joint</joint>
      <mimicJoint>R_bh_j23_joint</mimicJoint>
      <multiplier>0.344</multiplier>
    </plugin>
  </gazebo>
  <gazebo>
    <plugin filename="libgazebo_mimic_plugin.so" name="mimic_plugin">
      <joint>R_bh_j32_joint</joint>
      <mimicJoint>R_bh_j33_joint</mimicJoint>
      <multiplier>0.344</multiplier>
    </plugin>
  </gazebo>
  <gazebo reference="R_bh_base_link">
    <material>Gazebo/White</material>
    <turnGravityOff>False</turnGravityOff>
  </gazebo>
  <gazebo reference="R_bh_finger_31_link">
    <material>Gazebo/Grey</material>
    <turnGravityOff>False</turnGravityOff>
  </gazebo>
  <gazebo reference="R_bh_finger_32_link">
    <material>Gazebo/Grey</material>
    <turnGravityOff>False</turnGravityOff>
  </gazebo>
  <gazebo reference="R_bh_finger_33_link">
    <material>Gazebo/Grey</material>
    <turnGravityOff>False</turnGravityOff>
  </gazebo>
  <gazebo reference="R_bh_finger_11_link">
    <material>Gazebo/Grey</material>
    <turnGravityOff>False</turnGravityOff>
  </gazebo>
  <gazebo reference="R_bh_finger_12_link">
    <material>Gazebo/Grey</material>
    <turnGravityOff>False</turnGravityOff>
  </gazebo>
  <gazebo reference="R_bh_finger_13_link">
    <material>Gazebo/Grey</material>
    <turnGravityOff>False</turnGravityOff>
  </gazebo>
  <gazebo reference="R_bh_finger_21_link">
    <material>Gazebo/Grey</material>
    <turnGravityOff>False</turnGravityOff>
  </gazebo>
  <gazebo reference="R_bh_finger_22_link">
    <material>Gazebo/Grey</material>
    <turnGravityOff>False</turnGravityOff>
  </gazebo>
  <gazebo reference="R_bh_finger_23_link">
    <material>Gazebo/Grey</material>
    <turnGravityOff>False</turnGravityOff>
  </gazebo>
  <!-- ====================================== -->
  <!-- Left Arm-->
  <joint name="JLA0" type="fixed">
    <origin rpy="1.57079632679 -1.57079632679 -1.57079632679" xyz="-0.12314 -0.00635 1.32915"/>
    <parent link="Link_Body"/>
    <child link="LArm0"/>
    <axis xyz="0 0 1"/>
  </joint>
  <link name="LArm0">
    <inertial>
      <origin rpy="0 0 0" xyz="-0.00832 0.0 -0.0418"/>
      <mass value="2.367"/>
      <inertia ixx="0.00366" ixy="0.0" ixz="-0.0000208" iyy="0.00398" iyz="0.0" izz="0.00461"/>
    </inertial>
    <visual>
      <origin rpy="0 0 0" xyz="0 0 0"/>
      <geometry>
        <mesh filename="./ballbot_arm/meshes/v2020/link_base.stl"/>
      </geometry>
      <material name="grey"/>
    </visual>
    <collision>
      <origin rpy="0 0 0" xyz="0 0 0"/>
      <geometry>
        <mesh filename="./ballbot_arm/meshes/v2020/link_base.stl"/>
      </geometry>
    </collision>
  </link>
  <link name="LArm1">
    <inertial>
      <origin xyz="0.0 0.00329 0.0865"/>
      <mass value="4.181"/>
      <inertia ixx="0.0172" ixy="0.0000173" ixz="0.0" iyy="0.0170" iyz="-0.000935" izz="0.00602"/>
    </inertial>
    <visual>
      <origin rpy="0 0 0" xyz="0.0 0.0 0.0"/>
      <geometry>
        <mesh filename="./ballbot_arm/meshes/v2020/link_shoulder_2_base.stl"/>
      </geometry>
      <material name="brown"/>
    </visual>
    <collision>
      <origin rpy="0 0 0" xyz="0.0 0.0 -0.05525"/>
      <geometry>
        <cylinder length="0.1105" radius="0.05"/>
      </geometry>
      <material name="blue"/>
    </collision>
  </link>
  <link name="LArm2">
    <inertial>
      <origin xyz="-0.123 0.000 -0.0507"/>
      <mass value="1.832"/>
      <inertia ixx="0.00241" ixy="0.0" ixz="-0.000742" iyy="0.00559" iyz="0.0" izz="0.00563"/>
    </inertial>
    <visual>
      <origin rpy="0 0 0" xyz="0.0 0.0 0.0"/>
      <geometry>
        <mesh filename="./ballbot_arm/meshes/v2020/link_shoulder_2_uparm.stl"/>
      </geometry>
      <material name="grey"/>
    </visual>
    <collision>
      <origin rpy="0 0 0" xyz="0.0 0.0 -0.05525"/>
      <geometry>
        <cylinder length="0.1105" radius="0.05"/>
      </geometry>
      <material name="blue"/>
    </collision>
  </link>
  <link name="LArm3">
    <inertial>
      <origin xyz="0.0 -0.00963 0.0773"/>
      <mass value="1.821"/>
      <inertia ixx="0.00375" ixy="0.0" ixz="0.0" iyy="0.00338" iyz="0.000169" izz="0.00278"/>
    </inertial>
    <visual>
      <origin rpy="0 0 0" xyz="0.0 0.0 -0.02718"/>
      <geometry>
        <mesh filename="./ballbot_arm/meshes/v2020/link_upperarm.stl"/>
      </geometry>
      <material name="brown"/>
    </visual>
    <collision>
      <origin rpy="0 0 0" xyz="0.0 0.0 -0.05525"/>
      <geometry>
        <cylinder length="0.1105" radius="0.05"/>
      </geometry>
      <material name="blue"/>
    </collision>
  </link>
  <link name="LArm4">
    <inertial>
      <origin xyz="-0.0758 -0.0594 -0.0448"/>
      <mass value="1.105"/>
      <inertia ixx="0.00186" ixy="-0.000915" ixz="-0.000456" iyy="0.00276" iyz="-0.000276" izz="0.00356"/>
    </inertial>
    <visual>
      <origin rpy="0 0 0" xyz="0.0 0.0 0.0"/>
      <geometry>
        <mesh filename="./ballbot_arm/meshes/v2020/link_forearm.stl"/>
      </geometry>
      <material name="grey"/>
    </visual>
    <collision>
      <origin rpy="0 0 0" xyz="0.0 0.0 -0.05525"/>
      <geometry>
        <cylinder length="0.1105" radius="0.05"/>
      </geometry>
      <material name="blue"/>
    </collision>
  </link>
  <link name="LArm5">
    <inertial>
      <origin xyz="-0.00147 0.0 -0.0537"/>
      <mass value="0.973"/>
      <inertia ixx="0.00106" ixy="0.0" ixz="-0.0000188" iyy="0.00123" iyz="0.0" izz="0.00101"/>
    </inertial>
    <visual>
      <origin rpy="0 0 0" xyz="0.0 0.0 0.0"/>
      <geometry>
        <mesh filename="./ballbot_arm/meshes/v2020/link_forearm_2_wrist.stl"/>
      </geometry>
      <material name="brown"/>
    </visual>
    <collision>
      <origin rpy="0 0 0" xyz="0.0 0.0 0.0495"/>
      <geometry>
        <cylinder length="0.099" radius="0.0375"/>
      </geometry>
      <material name="blue"/>
    </collision>
  </link>
  <link name="LArm6">
    <inertial>
      <origin xyz="0.0947 0.00543 0.0386"/>
      <mass value="1.013"/>
      <inertia ixx="0.00106" ixy="-0.0000831" ixz="-0.000236" iyy="0.00193" iyz="-0.0000139" izz="0.00215"/>
    </inertial>
    <visual>
      <origin rpy="0 0 0" xyz="0.0 0.0 0.0"/>
      <geometry>
        <mesh filename="./ballbot_arm/meshes/v2020/link_wrist_mid.stl"/>
      </geometry>
      <material name="grey"/>
    </visual>
    <collision>
      <origin rpy="0 0 0" xyz="0.0 0.0 0.0495"/>
      <geometry>
        <cylinder length="0.099" radius="0.0375"/>
      </geometry>
      <material name="blue"/>
    </collision>
  </link>
  <link name="LArm7">
    <inertial>
      <origin xyz="0.0235 -0.000000178 0.0295"/>
      <mass value="0.195"/>
      <inertia ixx="0.000257" ixy="0.0" ixz="-0.0000691" iyy="0.000325" iyz="0.0" izz="0.000362"/>
    </inertial>
    <visual>
      <origin rpy="0 0 0" xyz="0.0 0.0 0.0"/>
      <geometry>
        <mesh filename="./ballbot_arm/meshes/v2020/link_wrist_2_hand.stl"/>
      </geometry>
      <material name="brown"/>
    </visual>
    <collision>
      <origin rpy="0 0 0" xyz="0.0 0.0 0.0495"/>
      <geometry>
        <cylinder length="0.099" radius="0.0375"/>
      </geometry>
      <material name="blue"/>
    </collision>
  </link>
  <joint name="JLA1" type="revolute">
    <origin rpy="0.0 0.0 0.0" xyz="0.0 0.0 0.0"/>
    <parent link="LArm0"/>
    <child link="LArm1"/>
    <limit effort="30.0" lower="-2.96705972839" upper="2.96705972839" velocity="3.0"/>
    <axis xyz="0 0 1"/>
    <dynamics damping="0.7" friction="0.5"/>
  </joint>
  <joint name="JLA2" type="revolute">
    <origin rpy="1.5707963705062866 -0.0 0.0" xyz="0.00000 -0.05436 0.14900"/>
    <parent link="LArm1"/>
    <child link="LArm2"/>
    <limit effort="30.0" lower="-1.57079632679" upper="0.0349065850399" velocity="3.0"/>
    <axis xyz="0 0 1"/>
    <dynamics damping="0.7" friction="0.5"/>
  </joint>
  <joint name="JLA3" type="revolute">
    <origin rpy="2.0344439357957036 1.5707962290814481 -1.1071487177940917" xyz="-0.17786 0.00000 -0.05436"/>
    <parent link="LArm2"/>
    <child link="LArm3"/>
    <limit effort="30.0" lower="-1.57079632679" upper="1.57079632679" velocity="3.0"/>
    <axis xyz="0 0 1"/>
    <dynamics damping="0.7" friction="0.5"/>
  </joint>
  <joint name="JLA4" type="revolute">
    <origin rpy="-2.3561944901923457 1.5707962635746238 2.3561944901923457" xyz="0.00000 -0.05436 0.08522"/>
    <parent link="LArm3"/>
    <child link="LArm4"/>
    <limit effort="30.0" lower="-2.79252680319" upper="0.349065850399" velocity="3.0"/>
    <axis xyz="0 0 1"/>
    <dynamics damping="0.7" friction="0.5"/>
  </joint>
  <joint name="JLA5" type="revolute">
    <origin rpy="-1.57079632679 -1.57079632679 -1.57079632679" xyz="-0.13200 -0.07000 -0.05073"/>
    <parent link="LArm4"/>
    <child link="LArm5"/>
    <limit effort="30.0" lower="-2.82743338823" upper="2.82743338823" velocity="3.0"/>
    <axis xyz="0 0 1"/>
    <dynamics damping="0.7" friction="0.5"/>
  </joint>
  <joint name="JLA6" type="revolute">
    <origin rpy="0 1.57079632679 0" xyz="-0.041150 0.0 -0.06000"/>
    <parent link="LArm5"/>
    <child link="LArm6"/>
    <limit effort="30.0" lower="-1.49599650171" upper="1.49599650171" velocity="3.0"/>
    <axis xyz="0 0 1"/>
    <dynamics damping="0.7" friction="0.5"/>
  </joint>
  <joint name="JLA7" type="revolute">
    <origin rpy="1.57079632679 0.0 0.0" xyz="0.10750 0.04650 0.041150"/>
    <parent link="LArm6"/>
    <child link="LArm7"/>
    <limit effort="30.0" lower="-1.49599650171" upper="1.49599650171" velocity="3.0"/>
    <axis xyz="0 0 1"/>
    <dynamics damping="0.7" friction="0.5"/>
  </joint>
  <link name="toolL">
    <inertial>
      <origin xyz="0.0 0.0 0.0"/>
      <mass value="1e-05"/>
      <inertia ixx="0.00001" ixy="0.0" ixz="0.0" iyy="0.00001" iyz="0.0" izz="0.00001"/>
    </inertial>
  </link>
  <joint name="LArm7-toolL" type="revolute">
    <origin rpy="0 1.57079632679 0" xyz="0.155 0 0.04065"/>
    <axis xyz="0 0 1"/>
    <parent link="LArm7"/>
    <child link="toolL"/>
  </joint>
  <!-- Knob hands -->
  <!-- <xacro:knob_hand prefix="L_" parent="toolL" material="blue">
    <origin xyz="0. 0. 0." rpy="0. 0. 0."/>
  </xacro:knob_hand> -->
  <!-- Left Intel RealSense Camera -->
  <!-- <xacro:IntelD435_mount_macro prefix="L_" parent="toolL" color="grey">
    <origin xyz="0 0 0.0" rpy="0 0 0"/>
  </xacro:IntelD435_mount_macro> -->
  <!-- <sensor_d435 parent="L_D435_Mount" name="LD435_camera">
    <origin xyz="-0.064427 0 0.016981" rpy="${DEG2RAD*0} ${-DEG2RAD*80} ${DEG2RAD*0} "/>
  </sensor_d435> -->
  <!-- Left  Barrett B4277 Mount -->
  <!-- <xacro:bhand_mount_macro prefix="L_" parent="L_D435_Mount">
      <origin xyz="0 0 0.006" rpy="0 0 0"/>
  </xacro:bhand_mount_macro> -->
  <!-- Left  Barrett Hand B282 -->
  <!-- <xacro:bhand_macro name="L_bh" parent="L_B4277_link">
    <origin xyz="0 0 0.008" rpy="0 0 0" />
  </xacro:bhand_macro> -->
  <!-- <xacro:bhand_macro name="L_bh" parent="toolL">
    <origin xyz="0 0 0.0" rpy="0 0 0" />
  </xacro:bhand_macro> -->
  <joint name="L_bh_base_joint" type="fixed">
    <origin rpy="0 -1.57079632679 3.14159265359" xyz="0.055 0 0.04065"/>
    <parent link="LArm7"/>
    <child link="L_bh_base_link"/>
  </joint>
  <!-- HAND BASE_LINK (RED) -->
  <link name="L_bh_base_link">
    <inertial>
      <mass value="3.0"/>
      <origin xyz="0 0 0"/>
      <inertia ixx="1.0" ixy="0.0" ixz="0.0" iyy="1.0" iyz="0.0" izz="1.0"/>
    </inertial>
    <visual>
      <origin rpy="0 0 0" xyz="0 0 0"/>
      <geometry>
        <mesh filename="./barrett_hand/meshes/palm_282.dae"/>
      </geometry>
      <material name="Grey">
        <color rgba="0.75 0.75 0.75 1.0"/>
      </material>
    </visual>
    <collision>
      <origin rpy="0 0 0 " xyz="0 0 0"/>
      <geometry>
        <mesh filename="./barrett_hand/meshes/palm_282.dae"/>
      </geometry>
      <contact_coefficients kd="1.0" kp="1000.0" mu="0"/>
    </collision>
  </link>
  <!-- finger 3 -->
  <!-- finger 31 link -->
  <link name="L_bh_finger_31_link">
    <inertial>
      <mass value="0.1"/>
      <origin rpy="0 0 0" xyz="-0.046 0 0"/>
      <inertia ixx="0.01" ixy="0" ixz="0" iyy="0.01" iyz="0" izz="0.01"/>
    </inertial>
    <visual>
      <origin rpy="0 0 0" xyz="-0.04 0 0"/>
      <geometry>
        <mesh filename="./barrett_hand/meshes/knuckle_fixed.dae"/>
      </geometry>
      <material name="Black"/>
    </visual>
    <collision>
      <origin rpy="0 0 0" xyz="-0.04 0 0"/>
      <geometry>
        <mesh filename="./barrett_hand/meshes/knuckle_fixed.dae"/>
      </geometry>
      <contact_coefficients kd="1.0" kp="1000.0" mu="0"/>
    </collision>
  </link>
  <!-- joint between BH_palm_link and BH_finger_31_link -->
  <!-- finger3 is the center finger and is fixed -->
  <joint name="L_bh_j31_joint" type="fixed">
    <parent link="L_bh_base_link"/>
    <child link="L_bh_finger_31_link"/>
    <origin rpy="0 0 -1.570796327" xyz="0 0 0.0252"/>
  </joint>
  <!-- finger 32 link -->
  <link name="L_bh_finger_32_link">
    <inertial>
      <mass value="0.1"/>
      <origin rpy="0 0 0" xyz="0 0 0"/>
      <inertia ixx="0.01" ixy="0" ixz="0" iyy="0.01" iyz="0" izz="0.01"/>
    </inertial>
    <visual>
      <origin rpy="0 0 0" xyz="0 0 0"/>
      <geometry>
        <mesh filename="./barrett_hand/meshes/finger.dae"/>
      </geometry>
      <material name="Blue"/>
    </visual>
    <collision>
      <origin rpy="0 0 0" xyz="0 0 0"/>
      <geometry>
        <mesh filename="./barrett_hand/meshes/finger.dae"/>
      </geometry>
      <contact_coefficients kd="1.0" kp="1000.0" mu="0"/>
    </collision>
  </link>
  <!-- joint between BH_finger_31_link and BH_finger_32_link -->
  <joint name="L_bh_j32_joint" type="revolute">
    <parent link="L_bh_finger_31_link"/>
    <child link="L_bh_finger_32_link"/>
    <origin rpy="1.5708 -8.8281E-17 0" xyz="-0.05 0 0.0339"/>
    <axis xyz="0 0 -1"/>
    <limit effort="30.0" lower="0.0" upper="2.44" velocity="2.0"/>
    <dynamics damping="0.7" friction="1.0"/>
  </joint>
  <transmission name="L_bh_j32_transmission">
    <type>transmission_interface/SimpleTransmission</type>
    <joint name="L_bh_j32_joint">
      <hardwareInterface>hardware_interface/PositionJointInterface</hardwareInterface>
    </joint>
    <actuator name="L_bh_j32">
      <hardwareInterface>hardware_interface/PositionJointInterface</hardwareInterface>
      <mechanicalReduction>1</mechanicalReduction>
      <motorTorqueConstant>1</motorTorqueConstant>
    </actuator>
  </transmission>
  <!-- finger 33 link -->
  <link name="L_bh_finger_33_link">
    <inertial>
      <mass value="0.1"/>
      <origin rpy="0 0 0" xyz="0 0 0"/>
      <inertia ixx="0.01" ixy="0" ixz="0" iyy="0.01" iyz="0" izz="0.01"/>
    </inertial>
    <visual>
      <origin rpy="0 0 0" xyz="0 0 0"/>
      <geometry>
        <mesh filename="./barrett_hand/meshes/finger_tip.dae"/>
      </geometry>
      <material name="Blue"/>
    </visual>
    <collision>
      <origin rpy="0 0 0" xyz="0 0 0"/>
      <geometry>
        <mesh filename="./barrett_hand/meshes/finger_tip.dae"/>
      </geometry>
      <contact_coefficients kd="1.0" kp="1000.0" mu="0"/>
    </collision>
  </link>
  <!-- joint between BH_finger_32_link and BH_finger_33_link -->
  <joint name="L_bh_j33_joint" type="revolute">
    <parent link="L_bh_finger_32_link"/>
    <child link="L_bh_finger_33_link"/>
    <origin rpy="0 0 0" xyz="-0.069936 0.003 0"/>
    <axis xyz="0 0 -1"/>
    <mimic joint="L_bh_j32_joint" multiplier="0.344262295082"/>
    <limit effort="30.0" lower="0.0" upper="0.84" velocity="2.0"/>
    <dynamics damping="0.7" friction="1.0"/>
  </joint>
  <transmission name="L_bh_j33_transmission">
    <type>transmission_interface/SimpleTransmission</type>
    <joint name="L_bh_j33_joint">
      <hardwareInterface>hardware_interface/PositionJointInterface</hardwareInterface>
    </joint>
    <actuator name="L_bh_j33">
      <hardwareInterface>hardware_interface/PositionJointInterface</hardwareInterface>
      <mechanicalReduction>1</mechanicalReduction>
      <motorTorqueConstant>1</motorTorqueConstant>
    </actuator>
  </transmission>
  <!-- finger 1 -->
  <!-- finger 11 link -->
  <link name="L_bh_finger_11_link">
    <inertial>
      <mass value="0.1"/>
      <origin rpy="0 0 0" xyz="-0.046 0 0"/>
      <inertia ixx="0.01" ixy="0" ixz="0" iyy="0.01" iyz="0" izz="0.01"/>
    </inertial>
    <visual>
      <origin rpy="0 0 0" xyz="0 0 0"/>
      <geometry>
        <mesh filename="./barrett_hand/meshes/knuckle.dae"/>
      </geometry>
      <material name="Green"/>
    </visual>
    <collision>
      <origin rpy="0 0 0" xyz="0 0 0"/>
      <geometry>
        <mesh filename="./barrett_hand/meshes/knuckle.dae"/>
      </geometry>
    </collision>
  </link>
  <!-- joint between BH_palm_link and BH_finger_11_link -->
  <joint name="L_bh_j11_joint" type="revolute">
    <parent link="L_bh_base_link"/>
    <child link="L_bh_finger_11_link"/>
    <origin rpy="0 0 1.5708" xyz="-0.025 0 0.0252"/>
    <axis xyz="0 0 -1"/>
    <limit effort="30.0" lower="0" upper="3.1416" velocity="2.0"/>
    <dynamics damping="0.7" friction="1.0"/>
  </joint>
  <transmission name="L_bh_j11_transmission">
    <type>transmission_interface/SimpleTransmission</type>
    <joint name="L_bh_j11_joint">
      <hardwareInterface>hardware_interface/PositionJointInterface</hardwareInterface>
    </joint>
    <actuator name="L_bh_j11">
      <hardwareInterface>hardware_interface/PositionJointInterface</hardwareInterface>
      <mechanicalReduction>1</mechanicalReduction>
      <motorTorqueConstant>1</motorTorqueConstant>
    </actuator>
  </transmission>
  <!-- finger 12 link -->
  <link name="L_bh_finger_12_link">
    <inertial>
      <mass value="0.1"/>
      <origin rpy="0 0 0" xyz="0 0 0"/>
      <inertia ixx="0.01" ixy="0" ixz="0" iyy="0.01" iyz="0" izz="0.01"/>
    </inertial>
    <visual>
      <origin rpy="0 0 0" xyz="0 0 0"/>
      <geometry>
        <mesh filename="./barrett_hand/meshes/finger.dae"/>
      </geometry>
      <material name="Blue"/>
    </visual>
    <collision>
      <origin rpy="0 0 0" xyz="0 0 0"/>
      <geometry>
        <mesh filename="./barrett_hand/meshes/finger.dae"/>
      </geometry>
      <contact_coefficients kd="1.0" kp="1000.0" mu="0"/>
    </collision>
  </link>
  <!-- joint between BH_finger_11_link and BH_finger_12_link -->
  <joint name="L_bh_j12_joint" type="revolute">
    <parent link="L_bh_finger_11_link"/>
    <child link="L_bh_finger_12_link"/>
    <origin rpy="1.5708 0 0" xyz="-0.05 0 0.0339"/>
    <axis xyz="0 0 -1"/>
    <limit effort="30.0" lower="0.0" upper="2.44" velocity="2.0"/>
    <dynamics damping="0.7" friction="1.0"/>
  </joint>
  <transmission name="L_bh_j12_transmission">
    <type>transmission_interface/SimpleTransmission</type>
    <joint name="L_bh_j12_joint">
      <hardwareInterface>hardware_interface/PositionJointInterface</hardwareInterface>
    </joint>
    <actuator name="L_bh_j12">
      <hardwareInterface>hardware_interface/PositionJointInterface</hardwareInterface>
      <mechanicalReduction>1</mechanicalReduction>
      <motorTorqueConstant>1</motorTorqueConstant>
    </actuator>
  </transmission>
  <!-- finger 13 link -->
  <link name="L_bh_finger_13_link">
    <inertial>
      <mass value="0.1"/>
      <origin rpy="0 0 0" xyz="0 0 0"/>
      <inertia ixx="0.01" ixy="0" ixz="0" iyy="0.01" iyz="0" izz="0.01"/>
    </inertial>
    <visual>
      <origin rpy="0 0 0" xyz="0 0 0"/>
      <geometry>
        <mesh filename="./barrett_hand/meshes/finger_tip.dae"/>
      </geometry>
      <material name="Blue"/>
    </visual>
    <collision>
      <origin rpy="0 0 0" xyz="0 0 0"/>
      <geometry>
        <mesh filename="./barrett_hand/meshes/finger_tip.dae"/>
      </geometry>
      <contact_coefficients kd="1.0" kp="1000.0" mu="0"/>
    </collision>
  </link>
  <!-- joint between BH_finger_12_link and BH_finger_13_link -->
  <joint name="L_bh_j13_joint" type="revolute">
    <parent link="L_bh_finger_12_link"/>
    <child link="L_bh_finger_13_link"/>
    <origin rpy="0 0 0" xyz="-0.069936 0.003 0"/>
    <axis xyz="0 0 -1"/>
    <mimic joint="L_bh_j12_joint" multiplier="0.344262295082"/>
    <limit effort="30.0" lower="0.0" upper="0.84" velocity="2.0"/>
    <dynamics damping="0.7" friction="1.0"/>
  </joint>
  <transmission name="L_bh_j13_transmission">
    <type>transmission_interface/SimpleTransmission</type>
    <joint name="L_bh_j13_joint">
      <hardwareInterface>hardware_interface/PositionJointInterface</hardwareInterface>
    </joint>
    <actuator name="L_bh_j13">
      <hardwareInterface>hardware_interface/PositionJointInterface</hardwareInterface>
      <mechanicalReduction>1</mechanicalReduction>
      <motorTorqueConstant>1</motorTorqueConstant>
    </actuator>
  </transmission>
  <!-- finger 2 -->
  <!-- finger 21 link -->
  <link name="L_bh_finger_21_link">
    <inertial>
      <mass value="0.1"/>
      <origin rpy="0 0 0" xyz="-0.046 0 0"/>
      <inertia ixx="0.01" ixy="0" ixz="0" iyy="0.01" iyz="0" izz="0.01"/>
    </inertial>
    <visual>
      <origin rpy="0 0 0" xyz="0 0 0"/>
      <geometry>
        <mesh filename="./barrett_hand/meshes/knuckle.dae"/>
      </geometry>
      <material name="Green"/>
    </visual>
    <collision>
      <origin rpy="0 0 0" xyz="0 0 0"/>
      <geometry>
        <mesh filename="./barrett_hand/meshes/knuckle.dae"/>
      </geometry>
    </collision>
  </link>
  <!-- joint between BH_palm_link and BH_finger_21_link -->
  <joint name="L_bh_j21_joint" type="revolute">
    <parent link="L_bh_base_link"/>
    <child link="L_bh_finger_21_link"/>
    <origin rpy="0 0 1.5708" xyz="0.025 0 0.0252"/>
    <axis xyz="0 0 1"/>
    <mimic joint="L_bh_j11_joint" multiplier="1"/>
    <limit effort="30.0" lower="0" upper="3.1416" velocity="2.0"/>
    <dynamics damping="0.7" friction="1.0"/>
  </joint>
  <transmission name="L_bh_j21_transmission">
    <type>transmission_interface/SimpleTransmission</type>
    <joint name="L_bh_j21_joint">
      <hardwareInterface>hardware_interface/PositionJointInterface</hardwareInterface>
    </joint>
    <actuator name="L_bh_j21">
      <hardwareInterface>hardware_interface/PositionJointInterface</hardwareInterface>
      <mechanicalReduction>1</mechanicalReduction>
      <motorTorqueConstant>1</motorTorqueConstant>
    </actuator>
  </transmission>
  <!-- finger 12 link -->
  <link name="L_bh_finger_22_link">
    <inertial>
      <mass value="0.1"/>
      <origin rpy="0 0 0" xyz="0 0 0"/>
      <inertia ixx="0.01" ixy="0" ixz="0" iyy="0.01" iyz="0" izz="0.01"/>
    </inertial>
    <visual>
      <origin rpy="0 0 0" xyz="0 0 0"/>
      <geometry>
        <mesh filename="./barrett_hand/meshes/finger.dae"/>
      </geometry>
      <material name="Blue"/>
    </visual>
    <collision>
      <origin rpy="0 0 0" xyz="0 0 0"/>
      <geometry>
        <mesh filename="./barrett_hand/meshes/finger.dae"/>
      </geometry>
      <contact_coefficients kd="1.0" kp="1000.0" mu="0"/>
    </collision>
  </link>
  <!-- joint between BH_finger_21_link and BH_finger_22_link -->
  <joint name="L_bh_j22_joint" type="revolute">
    <parent link="L_bh_finger_21_link"/>
    <child link="L_bh_finger_22_link"/>
    <origin rpy="1.5708 -8.8281E-17 0" xyz="-0.05 0 0.0339"/>
    <axis xyz="0 0 -1"/>
    <limit effort="30.0" lower="0.0" upper="2.44" velocity="2.0"/>
    <dynamics damping="0.7" friction="1.0"/>
  </joint>
  <transmission name="L_bh_j22_transmission">
    <type>transmission_interface/SimpleTransmission</type>
    <joint name="L_bh_j22_joint">
      <hardwareInterface>hardware_interface/PositionJointInterface</hardwareInterface>
    </joint>
    <actuator name="L_bh_j22">
      <hardwareInterface>hardware_interface/PositionJointInterface</hardwareInterface>
      <mechanicalReduction>1</mechanicalReduction>
      <motorTorqueConstant>1</motorTorqueConstant>
    </actuator>
  </transmission>
  <!-- finger 23 link -->
  <link name="L_bh_finger_23_link">
    <inertial>
      <mass value="0.1"/>
      <origin rpy="0 0 0" xyz="0 0 0"/>
      <inertia ixx="0.01" ixy="0" ixz="0" iyy="0.01" iyz="0" izz="0.01"/>
    </inertial>
    <visual>
      <origin rpy="0 0 0" xyz="0 0 0"/>
      <geometry>
        <mesh filename="./barrett_hand/meshes/finger_tip.dae"/>
      </geometry>
      <material name="Blue"/>
    </visual>
    <collision>
      <origin rpy="0 0 0" xyz="0 0 0"/>
      <geometry>
        <mesh filename="./barrett_hand/meshes/finger_tip.dae"/>
      </geometry>
      <contact_coefficients kd="1.0" kp="1000.0" mu="0"/>
    </collision>
  </link>
  <!-- joint between BH_finger_22_link and BH_finger_23_link -->
  <joint name="L_bh_j23_joint" type="revolute">
    <parent link="L_bh_finger_22_link"/>
    <child link="L_bh_finger_23_link"/>
    <origin rpy="0 0 0" xyz="-0.069936 0.003 0"/>
    <axis xyz="0 0 -1"/>
    <mimic joint="L_bh_j22_joint" multiplier="0.344262295082"/>
    <limit effort="30.0" lower="0.0" upper="0.84" velocity="2.0"/>
    <dynamics damping="0.7" friction="1.0"/>
  </joint>
  <transmission name="L_bh_j23_transmission">
    <type>transmission_interface/SimpleTransmission</type>
    <joint name="L_bh_j23_joint">
      <hardwareInterface>hardware_interface/PositionJointInterface</hardwareInterface>
    </joint>
    <actuator name="L_bh_j23">
      <hardwareInterface>hardware_interface/PositionJointInterface</hardwareInterface>
      <mechanicalReduction>1</mechanicalReduction>
      <motorTorqueConstant>1</motorTorqueConstant>
    </actuator>
  </transmission>
  <gazebo>
    <plugin filename="libgazebo_mimic_plugin.so" name="mimic_plugin">
      <joint>L_bh_j11_joint</joint>
      <mimicJoint>L_bh_j21_joint</mimicJoint>
      <multiplier>1</multiplier>
    </plugin>
  </gazebo>
  <gazebo>
    <plugin filename="libgazebo_mimic_plugin.so" name="mimic_plugin">
      <joint>L_bh_j12_joint</joint>
      <mimicJoint>L_bh_j13_joint</mimicJoint>
      <multiplier>0.344</multiplier>
    </plugin>
  </gazebo>
  <gazebo>
    <plugin filename="libgazebo_mimic_plugin.so" name="mimic_plugin">
      <joint>L_bh_j22_joint</joint>
      <mimicJoint>L_bh_j23_joint</mimicJoint>
      <multiplier>0.344</multiplier>
    </plugin>
  </gazebo>
  <gazebo>
    <plugin filename="libgazebo_mimic_plugin.so" name="mimic_plugin">
      <joint>L_bh_j32_joint</joint>
      <mimicJoint>L_bh_j33_joint</mimicJoint>
      <multiplier>0.344</multiplier>
    </plugin>
  </gazebo>
  <gazebo reference="L_bh_base_link">
    <material>Gazebo/White</material>
    <turnGravityOff>False</turnGravityOff>
  </gazebo>
  <gazebo reference="L_bh_finger_31_link">
    <material>Gazebo/Grey</material>
    <turnGravityOff>False</turnGravityOff>
  </gazebo>
  <gazebo reference="L_bh_finger_32_link">
    <material>Gazebo/Grey</material>
    <turnGravityOff>False</turnGravityOff>
  </gazebo>
  <gazebo reference="L_bh_finger_33_link">
    <material>Gazebo/Grey</material>
    <turnGravityOff>False</turnGravityOff>
  </gazebo>
  <gazebo reference="L_bh_finger_11_link">
    <material>Gazebo/Grey</material>
    <turnGravityOff>False</turnGravityOff>
  </gazebo>
  <gazebo reference="L_bh_finger_12_link">
    <material>Gazebo/Grey</material>
    <turnGravityOff>False</turnGravityOff>
  </gazebo>
  <gazebo reference="L_bh_finger_13_link">
    <material>Gazebo/Grey</material>
    <turnGravityOff>False</turnGravityOff>
  </gazebo>
  <gazebo reference="L_bh_finger_21_link">
    <material>Gazebo/Grey</material>
    <turnGravityOff>False</turnGravityOff>
  </gazebo>
  <gazebo reference="L_bh_finger_22_link">
    <material>Gazebo/Grey</material>
    <turnGravityOff>False</turnGravityOff>
  </gazebo>
  <gazebo reference="L_bh_finger_23_link">
    <material>Gazebo/Grey</material>
    <turnGravityOff>False</turnGravityOff>
  </gazebo>
</robot>

